2020-12-14 21:08:49,521 [DEBUG] /usr/lib/python3.9/site-packages/urllib3/connectionpool.py:939 [_new_conn] Starting new HTTPS connection (1): ipinfo.io:443
2020-12-14 21:08:49,941 [DEBUG] /usr/lib/python3.9/site-packages/urllib3/connectionpool.py:433 [_make_request] https://ipinfo.io:443 "GET /?token=26d03faada92e8 HTTP/1.1" 200 None
2020-12-14 21:08:50,630 [DEBUG] /home/luna/git/PyArchboot/modules/system_manager/unix_command.py:133 [command_output] No existing lvm volume detected
2020-12-14 21:08:50,660 [DEBUG] /home/luna/git/PyArchboot/modules/system_manager/unix_command.py:133 [command_output] No existing luks volume detected
2020-12-14 21:08:50,696 [DEBUG] /home/luna/git/PyArchboot/modules/system_manager/unix_command.py:133 [command_output] No existing ntfs volume detected
2020-12-14 21:08:50,702 [INFO] /home/luna/git/PyArchboot/modules/questioner/questions.py:53 [question_manager] use arrow keys to select an option
2020-12-14 21:08:50,704 [WARNING] /home/luna/git/PyArchboot/modules/questioner/questions.py:54 [question_manager] all data will be lost !
